Workbook
Name AvailableTeachers: _xlfn.ANCHORARRAY(Teacher_Grid!$B$28)

Sheet Mastersheet
A2: Monday | B2: Class | C2: P1 | D2: P2 | E2: P3 | F2: P4 | G2: P5 | H2: P6 | I2: P7 | J2: P8
B3: 1a | C3: {=IF( INDIRECT("TT_"&$B3&"!"& ADDRESS( MATCH(LOOKUP(ROW($A3),ROW($A$1:$A3)/($A$1:$A3<>""),$A$1:$A3), {"Monday","Tuesday","Wednesday","Thursday","Friday","Saturday"},0)+1, COLUMN()-1 ) )="","", INDIRECT("TT_"&$B3&"!"& ADDRESS( MATCH(LOOKUP(ROW($A3),ROW($A$1:$A3)/($A$1:$A3<>""),$A$1:$A3), {"Monday","Tuesday","Wednesday","Thursday","Friday","Saturday"},0)+1, COLUMN()-1 ) ) & " (" & INDIRECT("TT_"&$B3&"!"& ADDRESS( MATCH(LOOKUP(ROW($A3),ROW($A$1:$A3)/($A$1:$A3<>""),$A$1:$A3), {"Monday","Tuesday","Wednesday","Thursday","Friday","Saturday"},0)+9, COLUMN()-1 ) ) & ")" )} -> Library (SP) | D3: {=IF( INDIRECT("TT_"&$B3&"!"& ADDRESS( MATCH(LOOKUP(ROW($A3),ROW($A$1:$A3)/($A$1:$A3<>""),$A$1:$A3), {"Monday","Tuesday","Wednesday","Thursday","Friday","Saturday"},0)+1, COLUMN()-1 ) )="","", INDIRECT("TT_"&$B3&"!"& ADDRESS( MATCH(LOOKUP(ROW($A3),ROW($A$1:$A3)/($A$1:$A3<>""),$A$1:$A3), {"Monday","Tuesday","Wednesday","Thursday","Friday","Saturday"},0)+1, COLUMN()-1 ) ) & " (" & INDIRECT("TT_"&$B3&"!"& ADDRESS( MATCH(LOOKUP(ROW($A3),ROW($A$1:$A3)/($A$1:$A3<>""),$A$1:$A3), {"Monday","Tuesday","Wednesday","Thursday","Friday","Saturday"},0)+9, COLUMN()-1 ) ) & ")" )} -> English_Lit (NM) | E3: {=IF( INDIRECT("TT_"&$B3&"!"& ADDRESS( MATCH(LOOKUP(ROW($A3),ROW($A$1:$A3)/($A$1:$A3<>""),$A$1:$A3), {"Monday","Tuesday","Wednesday","Thursday","Friday","Saturday"},0)+1, COLUMN()-1 ) )="","", INDIRECT("TT_"&$B3&"!"& ADDRESS( MATCH(LOOKUP(ROW($A3),ROW($A$1:$A3)/($A$1:$A3<>""),$A$1:$A3), {"Monday","Tuesday","Wednesday","Thursday","Friday","Saturday"},0)+1, COLUMN()-1 ) ) & " (" & INDIRECT("TT_"&$B3&"!"& ADDRESS( MATCH(LOOKUP(ROW($A3),ROW($A$1:$A3)/($A$1:$A3<>""),$A$1:$A3), {"Monday","Tuesday","Wednesday","Thursday","Friday","Saturday"},0)+9, COLUMN()-1 ) ) & ")" )} -> Maths (NM) | F3: {=IF( INDIRECT("TT_"&$B3&"!"& ADDRESS( MATCH(LOOKUP(ROW($A3),ROW($A$1:$A3)/($A$1:$A3<>""),$A$1:$A3), {"Monday","Tuesday","Wednesday","Thursday","Friday","Saturday"},0)+1, COLUMN()-1 ) )="","", INDIRECT("TT_"&$B3&"!"& ADDRESS( MATCH(LOOKUP(ROW($A3),ROW($A$1:$A3)/($A$1:$A3<>""),$A$1:$A3), {"Monday","Tuesday","Wednesday","Thursday","Friday","Saturday"},0)+1, COLUMN()-1 ) ) & " (" & INDIRECT("TT_"&$B3&"!"& ADDRESS( MATCH(LOOKUP(ROW($A3),ROW($A$1:$A3)/($A$1:$A3<>""),$A$1:$A3), {"Monday","Tuesday","Wednesday","Thursday","Friday","Saturday"},0)+9, COLUMN()-1 ) ) & ")" )} -> GK (NM) | G3: {=IF( INDIRECT("TT_"&$B3&"!"& ADDRESS( MATCH(LOOKUP(ROW($A3),ROW($A$1:$A3)/($A$1:$A3<>""),$A$1:$A3), {"Monday","Tuesday","Wednesday","Thursday","Friday","Saturday"},0)+1, COLUMN()-1 ) )="","", INDIRECT("TT_"&$B3&"!"& ADDRESS( MATCH(LOOKUP(ROW($A3),ROW($A$1:$A3)/($A$1:$A3<>""),$A$1:$A3), {"Monday","Tuesday","Wednesday","Thursday","Friday","Saturday"},0)+1, COLUMN()-1 ) ) & " (" & INDIRECT("TT_"&$B3&"!"& ADDRESS( MATCH(LOOKUP(ROW($A3),ROW($A$1:$A3)/($A$1:$A3<>""),$A$1:$A3), {"Monday","Tuesday","Wednesday","Thursday","Friday","Saturday"},0)+9, COLUMN()-1 ) ) & ")" )} -> EVS (NM) | H3: {=IF( INDIRECT("TT_"&$B3&"!"& ADDRESS( MATCH(LOOKUP(ROW($A3),ROW($A$1:$A3)/($A$1:$A3<>""),$A$1:$A3), {"Monday","Tuesday","Wednesday","Thursday","Friday","Saturday"},0)+1, COLUMN()-1 ) )="","", INDIRECT("TT_"&$B3&"!"& ADDRESS( MATCH(LOOKUP(ROW($A3),ROW($A$1:$A3)/($A$1:$A3<>""),$A$1:$A3), {"Monday","Tuesday","Wednesday","Thursday","Friday","Saturday"},0)+1, COLUMN()-1 ) ) & " (" & INDIRECT("TT_"&$B3&"!"& ADDRESS( MATCH(LOOKUP(ROW($A3),ROW($A$1:$A3)/($A$1:$A3<>""),$A$1:$A3), {"Monday","Tuesday","Wednesday","Thursday","Friday","Saturday"},0)+9, COLUMN()-1 ) ) & ")" )} -> A/C (MP) | I3: {=IF( INDIRECT("TT_"&$B3&"!"& ADDRESS( MATCH(LOOKUP(ROW($A3),ROW($A$1:$A3)/($A$1:$A3<>""),$A$1:$A3), {"Monday","Tuesday","Wednesday","Thursday","Friday","Saturday"},0)+1, COLUMN()-1 ) )="","", INDIRECT("TT_"&$B3&"!"& ADDRESS( MATCH(LOOKUP(ROW($A3),ROW($A$1:$A3)/($A$1:$A3<>""),$A$1:$A3), {"Monday","Tuesday","Wednesday","Thursday","Friday","Saturday"},0)+1, COLUMN()-1 ) ) & " (" & INDIRECT("TT_"&$B3&"!"& ADDRESS( MATCH(LOOKUP(ROW($A3),ROW($A$1:$A3)/($A$1:$A3<>""),$A$1:$A3), {"Monday","Tuesday","Wednesday","Thursday","Friday","Saturday"},0)+9, COLUMN()-1 ) ) & ")" )} -> Hindi_Lit (NM) | J3: {=IF( INDIRECT("TT_"&$B3&"!"& ADDRESS( MATCH(LOOKUP(ROW($A3),ROW($A$1:$A3)/($A$1:$A3<>""),$A$1:$A3), {"Monday","Tuesday","Wednesday","Thursday","Friday","Saturday"},0)+1, COLUMN()-1 ) )="","", INDIRECT("TT_"&$B3&"!"& ADDRESS( MATCH(LOOKUP(ROW($A3),ROW($A$1:$A3)/($A$1:$A3<>""),$A$1:$A3), {"Monday","Tuesday","Wednesday","Thursday","Friday","Saturday"},0)+1, COLUMN()-1 ) ) & " (" & INDIRECT("TT_"&$B3&"!"& ADDRESS( MATCH(LOOKUP(ROW($A3),ROW($A$1:$A3)/($A$1:$A3<>""),$A$1:$A3), {"Monday","Tuesday","Wednesday","Thursday","Friday","Saturday"},0)+9, COLUMN()-1 ) ) & ")" )} -> Dance (SL)
B4: 1b | C4: {=IF( INDIRECT("TT_"&$B4&"!"& ADDRESS( MATCH(LOOKUP(ROW($A4),ROW($A$1:$A4)/($A$1:$A4<>""),$A$1:$A4), {"Monday","Tuesday","Wednesday","Thursday","Friday","Saturday"},0)+1, COLUMN()-1 ) )="","", INDIRECT("TT_"&$B4&"!"& ADDRESS( MATCH(LOOKUP(ROW($A4),ROW($A$1:$A4)/($A$1:$A4<>""),$A$1:$A4), {"Monday","Tuesday","Wednesday","Thursday","Friday","Saturday"},0)+1, COLUMN()-1 ) ) & " (" & INDIRECT("TT_"&$B4&"!"& ADDRESS( MATCH(LOOKUP(ROW($A4),ROW($A$1:$A4)/($A$1:$A4<>""),$A$1:$A4), {"Monday","Tuesday","Wednesday","Thursday","Friday","Saturday"},0)+9, COLUMN()-1 ) ) & ")" )} -> Library (SP) | D4: {=IF( INDIRECT("TT_"&$B4&"!"& ADDRESS( MATCH(LOOKUP(ROW($A4),ROW($A$1:$A4)/($A$1:$A4<>""),$A$1:$A4), {"Monday","Tuesday","Wednesday","Thursday","Friday","Saturday"},0)+1, COLUMN()-1 ) )="","", INDIRECT("TT_"&$B4&"!"& ADDRESS( MATCH(LOOKUP(ROW($A4),ROW($A$1:$A4)/($A$1:$A4<>""),$A$1:$A4), {"Monday","Tuesday","Wednesday","Thursday","Friday","Saturday"},0)+1, COLUMN()-1 ) ) & " (" & INDIRECT("TT_"&$B4&"!"& ADDRESS( MATCH(LOOKUP(ROW($A4),ROW($A$1:$A4)/($A$1:$A4<>""),$A$1:$A4), {"Monday","Tuesday","Wednesday","Thursday","Friday","Saturday"},0)+9, COLUMN()-1 ) ) & ")" )} -> Dance (SL) | E4: {=IF( INDIRECT("TT_"&$B4&"!"& ADDRESS( MATCH(LOOKUP(ROW($A4),ROW($A$1:$A4)/($A$1:$A4<>""),$A$1:$A4), {"Monday","Tuesday","Wednesday","Thursday","Friday","Saturday"},0)+1, COLUMN()-1 ) )="","", INDIRECT("TT_"&$B4&"!"& ADDRESS( MATCH(LOOKUP(ROW($A4),ROW($A$1:$A4)/($A$1:$A4<>""),$A$1:$A4), {"Monday","Tuesday","Wednesday","Thursday","Friday","Saturday"},0)+1, COLUMN()-1 ) ) & " (" & INDIRECT("TT_"&$B4&"!"& ADDRESS( MATCH(LOOKUP(ROW($A4),ROW($A$1:$A4)/($A$1:$A4<>""),$A$1:$A4), {"Monday","Tuesday","Wednesday","Thursday","Friday","Saturday"},0)+9, COLUMN()-1 ) ) & ")" )} -> Computer (TP) | F4: {=IF( INDIRECT("TT_"&$B4&"!"& ADDRESS( MATCH(LOOKUP(ROW($A4),ROW($A$1:$A4)/($A$1:$A4<>""),$A$1:$A4), {"Monday","Tuesday","Wednesday","Thursday","Friday","Saturday"},0)+1, COLUMN()-1 ) )="","", INDIRECT("TT_"&$B4&"!"& ADDRESS( MATCH(LOOKUP(ROW($A4),ROW($A$1:$A4)/($A$1:$A4<>""),$A$1:$A4), {"Monday","Tuesday","Wednesday","Thursday","Friday","Saturday"},0)+1, COLUMN()-1 ) ) & " (" & INDIRECT("TT_"&$B4&"!"& ADDRESS( MATCH(LOOKUP(ROW($A4),ROW($A$1:$A4)/($A$1:$A4<>""),$A$1:$A4), {"Monday","Tuesday","Wednesday","Thursday","Friday","Saturday"},0)+9, COLUMN()-1 ) ) & ")" )} -> Maths (TP) | G4: {=IF( INDIRECT("TT_"&$B4&"!"& ADDRESS( MATCH(LOOKUP(ROW($A4),ROW($A$1:$A4)/($A$1:$A4<>""),$A$1:$A4), {"Monday","Tuesday","Wednesday","Thursday","Friday","Saturday"},0)+1, COLUMN()-1 ) )="","", INDIRECT("TT_"&$B4&"!"& ADDRESS( MATCH(LOOKUP(ROW($A4),ROW($A$1:$A4)/($A$1:$A4<>""),$A$1:$A4), {"Monday","Tuesday","Wednesday","Thursday","Friday","Saturday"},0)+1, COLUMN()-1 ) ) & " (" & INDIRECT("TT_"&$B4&"!"& ADDRESS( MATCH(LOOKUP(ROW($A4),ROW($A$1:$A4)/($A$1:$A4<>""),$A$1:$A4), {"Monday","Tuesday","Wednesday","Thursday","Friday","Saturday"},0)+9, COLUMN()-1 ) ) & ")" )} -> English_Lit (TP) | H4: {=IF( INDIRECT("TT_"&$B4&"!"& ADDRESS( MATCH(LOOKUP(ROW($A4),ROW($A$1:$A4)/($A$1:$A4<>""),$A$1:$A4), {"Monday","Tuesday","Wednesday","Thursday","Friday","Saturday"},0)+1, COLUMN()-1 ) )="","", INDIRECT("TT_"&$B4&"!"& ADDRESS( MATCH(LOOKUP(ROW($A4),ROW($A$1:$A4)/($A$1:$A4<>""),$A$1:$A4), {"Monday","Tuesday","Wednesday","Thursday","Friday","Saturday"},0)+1, COLUMN()-1 ) ) & " (" & INDIRECT("TT_"&$B4&"!"& ADDRESS( MATCH(LOOKUP(ROW($A4),ROW($A$1:$A4)/($A$1:$A4<>""),$A$1:$A4), {"Monday","Tuesday","Wednesday","Thursday","Friday","Saturday"},0)+9, COLUMN()-1 ) ) & ")" )} -> GK (TP) | I4: {=IF( INDIRECT("TT_"&$B4&"!"& ADDRESS( MATCH(LOOKUP(ROW($A4),ROW($A$1:$A4)/($A$1:$A4<>""),$A$1:$A4), {"Monday","Tuesday","Wednesday","Thursday","Friday","Saturday"},0)+1, COLUMN()-1 ) )="","", INDIRECT("TT_"&$B4&"!"& ADDRESS( MATCH(LOOKUP(ROW($A4),ROW($A$1:$A4)/($A$1:$A4<>""),$A$1:$A4), {"Monday","Tuesday","Wednesday","Thursday","Friday","Saturday"},0)+1, COLUMN()-1 ) ) & " (" & INDIRECT("TT_"&$B4&"!"& ADDRESS( MATCH(LOOKUP(ROW($A4),ROW($A$1:$A4)/($A$1:$A4<>""),$A$1:$A4), {"Monday","Tuesday","Wednesday","Thursday","Friday","Saturday"},0)+9, COLUMN()-1 ) ) & ")" )} -> Hindi_Lit (TP) | J4: {=IF( INDIRECT("TT_"&$B4&"!"& ADDRESS( MATCH(LOOKUP(ROW($A4),ROW($A$1:$A4)/($A$1:$A4<>""),$A$1:$A4), {"Monday","Tuesday","Wednesday","Thursday","Friday","Saturday"},0)+1, COLUMN()-1 ) )="","", INDIRECT("TT_"&$B4&"!"& ADDRESS( MATCH(LOOKUP(ROW($A4),ROW($A$1:$A4)/($A$1:$A4<>""),$A$1:$A4), {"Monday","Tuesday","Wednesday","Thursday","Friday","Saturday"},0)+1, COLUMN()-1 ) ) & " (" & INDIRECT("TT_"&$B4&"!"& ADDRESS( MATCH(LOOKUP(ROW($A4),ROW($A$1:$A4)/($A$1:$A4<>""),$A$1:$A4), {"Monday","Tuesday","Wednesday","Thursday","Friday","Saturday"},0)+9, COLUMN()-1 ) ) & ")" )} -> EVS (TP)
B5: 2a | C5: {=IF( INDIRECT("TT_"&$B5&"!"& ADDRESS( MATCH(LOOKUP(ROW($A5),ROW($A$1:$A5)/($A$1:$A5<>""),$A$1:$A5), {"Monday","Tuesday","Wednesday","Thursday","Friday","Saturday"},0)+1, COLUMN()-1 ) )="","", INDIRECT("TT_"&$B5&"!"& ADDRESS( MATCH(LOOKUP(ROW($A5),ROW($A$1:$A5)/($A$1:$A5<>""),$A$1:$A5), {"Monday","Tuesday","Wednesday","Thursday","Friday","Saturday"},0)+1, COLUMN()-1 ) ) & " (" & INDIRECT("TT_"&$B5&"!"& ADDRESS( MATCH(LOOKUP(ROW($A5),ROW($A$1:$A5)/($A$1:$A5<>""),$A$1:$A5), {"Monday","Tuesday","Wednesday","Thursday","Friday","Saturday"},0)+9, COLUMN()-1 ) ) & ")" )} -> Maths (PB) | D5: {=IF( INDIRECT("TT_"&$B5&"!"& ADDRESS( MATCH(LOOKUP(ROW($A5),ROW($A$1:$A5)/($A$1:$A5<>""),$A$1:$A5), {"Monday","Tuesday","Wednesday","Thursday","Friday","Saturday"},0)+1, COLUMN()-1 ) )="","", INDIRECT("TT_"&$B5&"!"& ADDRESS( MATCH(LOOKUP(ROW($A5),ROW($A$1:$A5)/($A$1:$A5<>""),$A$1:$A5), {"Monday","Tuesday","Wednesday","Thursday","Friday","Saturday"},0)+1, COLUMN()-1 ) ) & " (" & INDIRECT("TT_"&$B5&"!"& ADDRESS( MATCH(LOOKUP(ROW($A5),ROW($A$1:$A5)/($A$1:$A5<>""),$A$1:$A5), {"Monday","Tuesday","Wednesday","Thursday","Friday","Saturday"},0)+9, COLUMN()-1 ) ) & ")" )} -> English_Lit (PB) | E5: {=IF( INDIRECT("TT_"&$B5&"!"& ADDRESS( MATCH(LOOKUP(ROW($A5),ROW($A$1:$A5)/($A$1:$A5<>""),$A$1:$A5), {"Monday","Tuesday","Wednesday","Thursday","Friday","Saturday"},0)+1, COLUMN()-1 ) )="","", INDIRECT("TT_"&$B5&"!"& ADDRESS( MATCH(LOOKUP(ROW($A5),ROW($A$1:$A5)/($A$1:$A5<>""),$A$1:$A5), {"Monday","Tuesday","Wednesday","Thursday","Friday","Saturday"},0)+1, COLUMN()-1 ) ) & " (" & INDIRECT("TT_"&$B5&"!"& ADDRESS( MATCH(LOOKUP(ROW($A5),ROW($A$1:$A5)/($A$1:$A5<>""),$A$1:$A5), {"Monday","Tuesday","Wednesday","Thursday","Friday","Saturday"},0)+9, COLUMN()-1 ) ) & ")" )} -> Dance (SL) | F5: {=IF( INDIRECT("TT_"&$B5&"!"& ADDRESS( MATCH(LOOKUP(ROW($A5),ROW($A$1:$A5)/($A$1:$A5<>""),$A$1:$A5), {"Monday","Tuesday","Wednesday","Thursday","Friday","Saturday"},0)+1, COLUMN()-1 ) )="","", INDIRECT("TT_"&$B5&"!"& ADDRESS( MATCH(LOOKUP(ROW($A5),ROW($A$1:$A5)/($A$1:$A5<>""),$A$1:$A5), {"Monday","Tuesday","Wednesday","Thursday","Friday","Saturday"},0)+1, COLUMN()-1 ) ) & " (" & INDIRECT("TT_"&$B5&"!"& ADDRESS( MATCH(LOOKUP(ROW($A5),ROW($A$1:$A5)/($A$1:$A5<>""),$A$1:$A5), {"Monday","Tuesday","Wednesday","Thursday","Friday","Saturday"},0)+9, COLUMN()-1 ) ) & ")" )} -> EVS (PB) | G5: {=IF( INDIRECT("TT_"&$B5&"!"& ADDRESS( MATCH(LOOKUP(ROW($A5),ROW($A$1:$A5)/($A$1:$A5<>""),$A$1:$A5), {"Monday","Tuesday","Wednesday","Thursday","Friday","Saturday"},0)+1, COLUMN()-1 ) )="","", INDIRECT("TT_"&$B5&"!"& ADDRESS( MATCH(LOOKUP(ROW($A5),ROW($A$1:$A5)/($A$1:$A5<>""),$A$1:$A5), {"Monday","Tuesday","Wednesday","Thursday","Friday","Saturday"},0)+1, COLUMN()-1 ) ) & " (" & INDIRECT("TT_"&$B5&"!"& ADDRESS( MATCH(LOOKUP(ROW($A5),ROW($A$1:$A5)/($A$1:$A5<>""),$A$1:$A5), {"Monday","Tuesday","Wednesday","Thursday","Friday","Saturday"},0)+9, COLUMN()-1 ) ) & ")" )} -> Hindi_Lit (PB) | H5: {=IF( INDIRECT("TT_"&$B5&"!"& ADDRESS( MATCH(LOOKUP(ROW($A5),ROW($A$1:$A5)/($A$1:$A5<>""),$A$1:$A5), {"Monday","Tuesday","Wednesday","Thursday","Friday","Saturday"},0)+1, COLUMN()-1 ) )="","", INDIRECT("TT_"&$B5&"!"& ADDRESS( MATCH(LOOKUP(ROW($A5),ROW($A$1:$A5)/($A$1:$A5<>""),$A$1:$A5), {"Monday","Tuesday","Wednesday","Thursday","Friday","Saturday"},0)+1, COLUMN()-1 ) ) & " (" & INDIRECT("TT_"&$B5&"!"& ADDRESS( MATCH(LOOKUP(ROW($A5),ROW($A$1:$A5)/($A$1:$A5<>""),$A$1:$A5), {"Monday","Tuesday","Wednesday","Thursday","Friday","Saturday"},0)+9, COLUMN()-1 ) ) & ")" )} -> Maths (PB) | I5: {=IF( INDIRECT("TT_"&$B5&"!"& ADDRESS( MATCH(LOOKUP(ROW($A5),ROW($A$1:$A5)/($A$1:$A5<>""),$A$1:$A5), {"Monday","Tuesday","Wednesday","Thursday","Friday","Saturday"},0)+1, COLUMN()-1 ) )="","", INDIRECT("TT_"&$B5&"!"& ADDRESS( MATCH(LOOKUP(ROW($A5),ROW($A$1:$A5)/($A$1:$A5<>""),$A$1:$A5), {"Monday","Tuesday","Wednesday","Thursday","Friday","Saturday"},0)+1, COLUMN()-1 ) ) & " (" & INDIRECT("TT_"&$B5&"!"& ADDRESS( MATCH(LOOKUP(ROW($A5),ROW($A$1:$A5)/($A$1:$A5<>""),$A$1:$A5), {"Monday","Tuesday","Wednesday","Thursday","Friday","Saturday"},0)+9, COLUMN()-1 ) ) & ")" )} -> GK (PB) | J5: {=IF( INDIRECT("TT_"&$B5&"!"& ADDRESS( MATCH(LOOKUP(ROW($A5),ROW($A$1:$A5)/($A$1:$A5<>""),$A$1:$A5), {"Monday","Tuesday","Wednesday","Thursday","Friday","Saturday"},0)+1, COLUMN()-1 ) )="","", INDIRECT("TT_"&$B5&"!"& ADDRESS( MATCH(LOOKUP(ROW($A5),ROW($A$1:$A5)/($A$1:$A5<>""),$A$1:$A5), {"Monday","Tuesday","Wednesday","Thursday","Friday","Saturday"},0)+1, COLUMN()-1 ) ) & " (" & INDIRECT("TT_"&$B5&"!"& ADDRESS( MATCH(LOOKUP(ROW($A5),ROW($A$1:$A5)/($A$1:$A5<>""),$A$1:$A5), {"Monday","Tuesday","Wednesday","Thursday","Friday","Saturday"},0)+9, COLUMN()-1 ) ) & ")" )} -> EVS (PB)
B6: 2b | C6: {=IF( INDIRECT("TT_"&$B6&"!"& ADDRESS( MATCH(LOOKUP(ROW($A6),ROW($A$1:$A6)/($A$1:$A6<>""),$A$1:$A6), {"Monday","Tuesday","Wednesday","Thursday","Friday","Saturday"},0)+1, COLUMN()-1 ) )="","", INDIRECT("TT_"&$B6&"!"& ADDRESS( MATCH(LOOKUP(ROW($A6),ROW($A$1:$A6)/($A$1:$A6<>""),$A$1:$A6), {"Monday","Tuesday","Wednesday","Thursday","Friday","Saturday"},0)+1, COLUMN()-1 ) ) & " (" & INDIRECT("TT_"&$B6&"!"& ADDRESS( MATCH(LOOKUP(ROW($A6),ROW($A$1:$A6)/($A$1:$A6<>""),$A$1:$A6), {"Monday","Tuesday","Wednesday","Thursday","Friday","Saturday"},0)+9, COLUMN()-1 ) ) & ")" )} -> Computer (NP) | D6: {=IF( INDIRECT("TT_"&$B6&"!"& ADDRESS( MATCH(LOOKUP(ROW($A6),ROW($A$1:$A6)/($A$1:$A6<>""),$A$1:$A6), {"Monday","Tuesday","Wednesday","Thursday","Friday","Saturday"},0)+1, COLUMN()-1 ) )="","", INDIRECT("TT_"&$B6&"!"& ADDRESS( MATCH(LOOKUP(ROW($A6),ROW($A$1:$A6)/($A$1:$A6<>""),$A$1:$A6), {"Monday","Tuesday","Wednesday","Thursday","Friday","Saturday"},0)+1, COLUMN()-1 ) ) & " (" & INDIRECT("TT_"&$B6&"!"& ADDRESS( MATCH(LOOKUP(ROW($A6),ROW($A$1:$A6)/($A$1:$A6<>""),$A$1:$A6), {"Monday","Tuesday","Wednesday","Thursday","Friday","Saturday"},0)+9, COLUMN()-1 ) ) & ")" )} -> Maths (SU) | E6: {=IF( INDIRECT("TT_"&$B6&"!"& ADDRESS( MATCH(LOOKUP(ROW($A6),ROW($A$1:$A6)/($A$1:$A6<>""),$A$1:$A6), {"Monday","Tuesday","Wednesday","Thursday","Friday","Saturday"},0)+1, COLUMN()-1 ) )="","", INDIRECT("TT_"&$B6&"!"& ADDRESS( MATCH(LOOKUP(ROW($A6),ROW($A$1:$A6)/($A$1:$A6<>""),$A$1:$A6), {"Monday","Tuesday","Wednesday","Thursday","Friday","Saturday"},0)+1, COLUMN()-1 ) ) & " (" & INDIRECT("TT_"&$B6&"!"& ADDRESS( MATCH(LOOKUP(ROW($A6),ROW($A$1:$A6)/($A$1:$A6<>""),$A$1:$A6), {"Monday","Tuesday","Wednesday","Thursday","Friday","Saturday"},0)+9, COLUMN()-1 ) ) & ")" )} -> English_Lit (SU) | F6: {=IF( INDIRECT("TT_"&$B6&"!"& ADDRESS( MATCH(LOOKUP(ROW($A6),ROW($A$1:$A6)/($A$1:$A6<>""),$A$1:$A6), {"Monday","Tuesday","Wednesday","Thursday","Friday","Saturday"},0)+1, COLUMN()-1 ) )="","", INDIRECT("TT_"&$B6&"!"& ADDRESS( MATCH(LOOKUP(ROW($A6),ROW($A$1:$A6)/($A$1:$A6<>""),$A$1:$A6), {"Monday","Tuesday","Wednesday","Thursday","Friday","Saturday"},0)+1, COLUMN()-1 ) ) & " (" & INDIRECT("TT_"&$B6&"!"& ADDRESS( MATCH(LOOKUP(ROW($A6),ROW($A$1:$A6)/($A$1:$A6<>""),$A$1:$A6), {"Monday","Tuesday","Wednesday","Thursday","Friday","Saturday"},0)+9, COLUMN()-1 ) ) & ")" )} -> EVS (VR) | G6: {=IF( INDIRECT("TT_"&$B6&"!"& ADDRESS( MATCH(LOOKUP(ROW($A6),ROW($A$1:$A6)/($A$1:$A6<>""),$A$1:$A6), {"Monday","Tuesday","Wednesday","Thursday","Friday","Saturday"},0)+1, COLUMN()-1 ) )="","", INDIRECT("TT_"&$B6&"!"& ADDRESS( MATCH(LOOKUP(ROW($A6),ROW($A$1:$A6)/($A$1:$A6<>""),$A$1:$A6), {"Monday","Tuesday","Wednesday","Thursday","Friday","Saturday"},0)+1, COLUMN()-1 ) ) & " (" & INDIRECT("TT_"&$B6&"!"& ADDRESS( MATCH(LOOKUP(ROW($A6),ROW($A$1:$A6)/($A$1:$A6<>""),$A$1:$A6), {"Monday","Tuesday","Wednesday","Thursday","Friday","Saturday"},0)+9, COLUMN()-1 ) ) & ")" )} -> Hindi_Lang (SU) | H6: {=IF( INDIRECT("TT_"&$B6&"!"& ADDRESS( MATCH(LOOKUP(ROW($A6),ROW($A$1:$A6)/($A$1:$A6<>""),$A$1:$A6), {"Monday","Tuesday","Wednesday","Thursday","Friday","Saturday"},0)+1, COLUMN()-1 ) )="","", INDIRECT("TT_"&$B6&"!"& ADDRESS( MATCH(LOOKUP(ROW($A6),ROW($A$1:$A6)/($A$1:$A6<>""),$A$1:$A6), {"Monday","Tuesday","Wednesday","Thursday","Friday","Saturday"},0)+1, COLUMN()-1 ) ) & " (" & INDIRECT("TT_"&$B6&"!"& ADDRESS( MATCH(LOOKUP(ROW($A6),ROW($A$1:$A6)/($A$1:$A6<>""),$A$1:$A6), {"Monday","Tuesday","Wednesday","Thursday","Friday","Saturday"},0)+9, COLUMN()-1 ) ) & ")" )} -> Maths (SU) | I6: {=IF( INDIRECT("TT_"&$B6&"!"& ADDRESS( MATCH(LOOKUP(ROW($A6),ROW($A$1:$A6)/($A$1:$A6<>""),$A$1:$A6), {"Monday","Tuesday","Wednesday","Thursday","Friday","Saturday"},0)+1, COLUMN()-1 ) )="","", INDIRECT("TT_"&$B6&"!"& ADDRESS( MATCH(LOOKUP(ROW($A6),ROW($A$1:$A6)/($A$1:$A6<>""),$A$1:$A6), {"Monday","Tuesday","Wednesday","Thursday","Friday","Saturday"},0)+1, COLUMN()-1 ) ) & " (" & INDIRECT("TT_"&$B6&"!"& ADDRESS( MATCH(LOOKUP(ROW($A6),ROW($A$1:$A6)/($A$1:$A6<>""),$A$1:$A6), {"Monday","Tuesday","Wednesday","Thursday","Friday","Saturday"},0)+9, COLUMN()-1 ) ) & ")" )} -> Hindi_Lit (SU) | J6: {=IF( INDIRECT("TT_"&$B6&"!"& ADDRESS( MATCH(LOOKUP(ROW($A6),ROW($A$1:$A6)/($A$1:$A6<>""),$A$1:$A6), {"Monday","Tuesday","Wednesday","Thursday","Friday","Saturday"},0)+1, COLUMN()-1 ) )="","", INDIRECT("TT_"&$B6&"!"& ADDRESS( MATCH(LOOKUP(ROW($A6),ROW($A$1:$A6)/($A$1:$A6<>""),$A$1:$A6), {"Monday","Tuesday","Wednesday","Thursday","Friday","Saturday"},0)+1, COLUMN()-1 ) ) & " (" & INDIRECT("TT_"&$B6&"!"& ADDRESS( MATCH(LOOKUP(ROW($A6),ROW($A$1:$A6)/($A$1:$A6<>""),$A$1:$A6), {"Monday","Tuesday","Wednesday","Thursday","Friday","Saturday"},0)+9, COLUMN()-1 ) ) & ")" )} -> EVS (VR)
B7: 3a | C7: {=IF( INDIRECT("TT_"&$B7&"!"& ADDRESS( MATCH(LOOKUP(ROW($A7),ROW($A$1:$A7)/($A$1:$A7<>""),$A$1:$A7), {"Monday","Tuesday","Wednesday","Thursday","Friday","Saturday"},0)+1, COLUMN()-1 ) )="","", INDIRECT("TT_"&$B7&"!"& ADDRESS( MATCH(LOOKUP(ROW($A7),ROW($A$1:$A7)/($A$1:$A7<>""),$A$1:$A7), {"Monday","Tuesday","Wednesday","Thursday","Friday","Saturday"},0)+1, COLUMN()-1 ) ) & " (" & INDIRECT("TT_"&$B7&"!"& ADDRESS( MATCH(LOOKUP(ROW($A7),ROW($A$1:$A7)/($A$1:$A7<>""),$A$1:$A7), {"Monday","Tuesday","Wednesday","Thursday","Friday","Saturday"},0)+9, COLUMN()-1 ) ) & ")" )} -> Games (SZ) | D7: {=IF( INDIRECT("TT_"&$B7&"!"& ADDRESS( MATCH(LOOKUP(ROW($A7),ROW($A$1:$A7)/($A$1:$A7<>""),$A$1:$A7), {"Monday","Tuesday","Wednesday","Thursday","Friday","Saturday"},0)+1, COLUMN()-1 ) )="","", INDIRECT("TT_"&$B7&"!"& ADDRESS( MATCH(LOOKUP(ROW($A7),ROW($A$1:$A7)/($A$1:$A7<>""),$A$1:$A7), {"Monday","Tuesday","Wednesday","Thursday","Friday","Saturday"},0)+1, COLUMN()-1 ) ) & " (" & INDIRECT("TT_"&$B7&"!"& ADDRESS( MATCH(LOOKUP(ROW($A7),ROW($A$1:$A7)/($A$1:$A7<>""),$A$1:$A7), {"Monday","Tuesday","Wednesday","Thursday","Friday","Saturday"},0)+9, COLUMN()-1 ) ) & ")" )} -> English_Lit (AN) | E7: {=IF( INDIRECT("TT_"&$B7&"!"& ADDRESS( MATCH(LOOKUP(ROW($A7),ROW($A$1:$A7)/($A$1:$A7<>""),$A$1:$A7), {"Monday","Tuesday","Wednesday","Thursday","Friday","Saturday"},0)+1, COLUMN()-1 ) )="","", INDIRECT("TT_"&$B7&"!"& ADDRESS( MATCH(LOOKUP(ROW($A7),ROW($A$1:$A7)/($A$1:$A7<>""),$A$1:$A7), {"Monday","Tuesday","Wednesday","Thursday","Friday","Saturday"},0)+1, COLUMN()-1 ) ) & " (" & INDIRECT("TT_"&$B7&"!"& ADDRESS( MATCH(LOOKUP(ROW($A7),ROW($A$1:$A7)/($A$1:$A7<>""),$A$1:$A7), {"Monday","Tuesday","Wednesday","Thursday","Friday","Saturday"},0)+9, COLUMN()-1 ) ) & ")" )} -> Science (VR) | F7: {=IF( INDIRECT("TT_"&$B7&"!"& ADDRESS( MATCH(LOOKUP(ROW($A7),ROW($A$1:$A7)/($A$1:$A7<>""),$A$1:$A7), {"Monday","Tuesday","Wednesday","Thursday","Friday","Saturday"},0)+1, COLUMN()-1 ) )="","", INDIRECT("TT_"&$B7&"!"& ADDRESS( MATCH(LOOKUP(ROW($A7),ROW($A$1:$A7)/($A$1:$A7<>""),$A$1:$A7), {"Monday","Tuesday","Wednesday","Thursday","Friday","Saturday"},0)+1, COLUMN()-1 ) ) & " (" & INDIRECT("TT_"&$B7&"!"& ADDRESS( MATCH(LOOKUP(ROW($A7),ROW($A$1:$A7)/($A$1:$A7<>""),$A$1:$A7), {"Monday","Tuesday","Wednesday","Thursday","Friday","Saturday"},0)+9, COLUMN()-1 ) ) & ")" )} -> Music (MG) | G7: {=IF( INDIRECT("TT_"&$B7&"!"& ADDRESS( MATCH(LOOKUP(ROW($A7),ROW($A$1:$A7)/($A$1:$A7<>""),$A$1:$A7), {"Monday","Tuesday","Wednesday","Thursday","Friday","Saturday"},0)+1, COLUMN()-1 ) )="","", INDIRECT("TT_"&$B7&"!"& ADDRESS( MATCH(LOOKUP(ROW($A7),ROW($A$1:$A7)/($A$1:$A7<>""),$A$1:$A7), {"Monday","Tuesday","Wednesday","Thursday","Friday","Saturday"},0)+1, COLUMN()-1 ) ) & " (" & INDIRECT("TT_"&$B7&"!"& ADDRESS( MATCH(LOOKUP(ROW($A7),ROW($A$1:$A7)/($A$1:$A7<>""),$A$1:$A7), {"Monday","Tuesday","Wednesday","Thursday","Friday","Saturday"},0)+9, COLUMN()-1 ) ) & ")" )} -> Maths (DK) | H7: {=IF( INDIRECT("TT_"&$B7&"!"& ADDRESS( MATCH(LOOKUP(ROW($A7),ROW($A$1:$A7)/($A$1:$A7<>""),$A$1:$A7), {"Monday","Tuesday","Wednesday","Thursday","Friday","Saturday"},0)+1, COLUMN()-1 ) )="","", INDIRECT("TT_"&$B7&"!"& ADDRESS( MATCH(LOOKUP(ROW($A7),ROW($A$1:$A7)/($A$1:$A7<>""),$A$1:$A7), {"Monday","Tuesday","Wednesday","Thursday","Friday","Saturday"},0)+1, COLUMN()-1 ) ) & " (" & INDIRECT("TT_"&$B7&"!"& ADDRESS( MATCH(LOOKUP(ROW($A7),ROW($A$1:$A7)/($A$1:$A7<>""),$A$1:$A7), {"Monday","Tuesday","Wednesday","Thursday","Friday","Saturday"},0)+9, COLUMN()-1 ) ) & ")" )} -> SSt (NT) | I7: {=IF( INDIRECT("TT_"&$B7&"!"& ADDRESS( MATCH(LOOKUP(ROW($A7),ROW($A$1:$A7)/($A$1:$A7<>""),$A$1:$A7), {"Monday","Tuesday","Wednesday","Thursday","Friday","Saturday"},0)+1, COLUMN()-1 ) )="","", INDIRECT("TT_"&$B7&"!"& ADDRESS( MATCH(LOOKUP(ROW($A7),ROW($A$1:$A7)/($A$1:$A7<>""),$A$1:$A7), {"Monday","Tuesday","Wednesday","Thursday","Friday","Saturday"},0)+1, COLUMN()-1 ) ) & " (" & INDIRECT("TT_"&$B7&"!"& ADDRESS( MATCH(LOOKUP(ROW($A7),ROW($A$1:$A7)/($A$1:$A7<>""),$A$1:$A7), {"Monday","Tuesday","Wednesday","Thursday","Friday","Saturday"},0)+9, COLUMN()-1 ) ) & ")" )} -> Dance (SL) | J7: {=IF( INDIRECT("TT_"&$B7&"!"& ADDRESS( MATCH(LOOKUP(ROW($A7),ROW($A$1:$A7)/($A$1:$A7<>""),$A$1:$A7), {"Monday","Tuesday","Wednesday","Thursday","Friday","Saturday"},0)+1, COLUMN()-1 ) )="","", INDIRECT("TT_"&$B7&"!"& ADDRESS( MATCH(LOOKUP(ROW($A7),ROW($A$1:$A7)/($A$1:$A7<>""),$A$1:$A7), {"Monday","Tuesday","Wednesday","Thursday","Friday","Saturday"},0)+1, COLUMN()-1 ) ) & " (" & INDIRECT("TT_"&$B7&"!"& ADDRESS( MATCH(LOOKUP(ROW($A7),ROW($A$1:$A7)/($A$1:$A7<>""),$A$1:$A7), {"Monday","Tuesday","Wednesday","Thursday","Friday","Saturday"},0)+9, COLUMN()-1 ) ) & ")" )} -> Hindi_Lit (MB)
B8: 3b | C8: {=IF( INDIRECT("TT_"&$B8&"!"& ADDRESS( MATCH(LOOKUP(ROW($A8),ROW($A$1:$A8)/($A$1:$A8<>""),$A$1:$A8), {"Monday","Tuesday","Wednesday","Thursday","Friday","Saturday"},0)+1, COLUMN()-1 ) )="","", INDIRECT("TT_"&$B8&"!"& ADDRESS( MATCH(LOOKUP(ROW($A8),ROW($A$1:$A8)/($A$1:$A8<>""),$A$1:$A8), {"Monday","Tuesday","Wednesday","Thursday","Friday","Saturday"},0)+1, COLUMN()-1 ) ) & " (" & INDIRECT("TT_"&$B8&"!"& ADDRESS( MATCH(LOOKUP(ROW($A8),ROW($A$1:$A8)/($A$1:$A8<>""),$A$1:$A8), {"Monday","Tuesday","Wednesday","Thursday","Friday","Saturday"},0)+9, COLUMN()-1 ) ) & ")" )} -> English_Lit (KB) | D8: {=IF( INDIRECT("TT_"&$B8&"!"& ADDRESS( MATCH(LOOKUP(ROW($A8),ROW($A$1:$A8)/($A$1:$A8<>""),$A$1:$A8), {"Monday","Tuesday","Wednesday","Thursday","Friday","Saturday"},0)+1, COLUMN()-1 ) )="","", INDIRECT("TT_"&$B8&"!"& ADDRESS( MATCH(LOOKUP(ROW($A8),ROW($A$1:$A8)/($A$1:$A8<>""),$A$1:$A8), {"Monday","Tuesday","Wednesday","Thursday","Friday","Saturday"},0)+1, COLUMN()-1 ) ) & " (" & INDIRECT("TT_"&$B8&"!"& ADDRESS( MATCH(LOOKUP(ROW($A8),ROW($A$1:$A8)/($A$1:$A8<>""),$A$1:$A8), {"Monday","Tuesday","Wednesday","Thursday","Friday","Saturday"},0)+9, COLUMN()-1 ) ) & ")" )} -> Science (VR) | E8: {=IF( INDIRECT("TT_"&$B8&"!"& ADDRESS( MATCH(LOOKUP(ROW($A8),ROW($A$1:$A8)/($A$1:$A8<>""),$A$1:$A8), {"Monday","Tuesday","Wednesday","Thursday","Friday","Saturday"},0)+1, COLUMN()-1 ) )="","", INDIRECT("TT_"&$B8&"!"& ADDRESS( MATCH(LOOKUP(ROW($A8),ROW($A$1:$A8)/($A$1:$A8<>""),$A$1:$A8), {"Monday","Tuesday","Wednesday","Thursday","Friday","Saturday"},0)+1, COLUMN()-1 ) ) & " (" & INDIRECT("TT_"&$B8&"!"& ADDRESS( MATCH(LOOKUP(ROW($A8),ROW($A$1:$A8)/($A$1:$A8<>""),$A$1:$A8), {"Monday","Tuesday","Wednesday","Thursday","Friday","Saturday"},0)+9, COLUMN()-1 ) ) & ")" )} -> A/C (MP) | F8: {=IF( INDIRECT("TT_"&$B8&"!"& ADDRESS( MATCH(LOOKUP(ROW($A8),ROW($A$1:$A8)/($A$1:$A8<>""),$A$1:$A8), {"Monday","Tuesday","Wednesday","Thursday","Friday","Saturday"},0)+1, COLUMN()-1 ) )="","", INDIRECT("TT_"&$B8&"!"& ADDRESS( MATCH(LOOKUP(ROW($A8),ROW($A$1:$A8)/($A$1:$A8<>""),$A$1:$A8), {"Monday","Tuesday","Wednesday","Thursday","Friday","Saturday"},0)+1, COLUMN()-1 ) ) & " (" & INDIRECT("TT_"&$B8&"!"& ADDRESS( MATCH(LOOKUP(ROW($A8),ROW($A$1:$A8)/($A$1:$A8<>""),$A$1:$A8), {"Monday","Tuesday","Wednesday","Thursday","Friday","Saturday"},0)+9, COLUMN()-1 ) ) & ")" )} -> Maths (SU) | G8: {=IF( INDIRECT("TT_"&$B8&"!"& ADDRESS( MATCH(LOOKUP(ROW($A8),ROW($A$1:$A8)/($A$1:$A8<>""),$A$1:$A8), {"Monday","Tuesday","Wednesday","Thursday","Friday","Saturday"},0)+1, COLUMN()-1 ) )="","", INDIRECT("TT_"&$B8&"!"& ADDRESS( MATCH(LOOKUP(ROW($A8),ROW($A$1:$A8)/($A$1:$A8<>""),$A$1:$A8), {"Monday","Tuesday","Wednesday","Thursday","Friday","Saturday"},0)+1, COLUMN()-1 ) ) & " (" & INDIRECT("TT_"&$B8&"!"& ADDRESS( MATCH(LOOKUP(ROW($A8),ROW($A$1:$A8)/($A$1:$A8<>""),$A$1:$A8), {"Monday","Tuesday","Wednesday","Thursday","Friday","Saturday"},0)+9, COLUMN()-1 ) ) & ")" )} -> SSt (NT) | H8: {=IF( INDIRECT("TT_"&$B8&"!"& ADDRESS( MATCH(LOOKUP(ROW($A8),ROW($A$1:$A8)/($A$1:$A8<>""),$A$1:$A8), {"Monday","Tuesday","Wednesday","Thursday","Friday","Saturday"},0)+1, COLUMN()-1 ) )="","", INDIRECT("TT_"&$B8&"!"& ADDRESS( MATCH(LOOKUP(ROW($A8),ROW($A$1:$A8)/($A$1:$A8<>""),$A$1:$A8), {"Monday","Tuesday","Wednesday","Thursday","Friday","Saturday"},0)+1, COLUMN()-1 ) ) & " (" & INDIRECT("TT_"&$B8&"!"& ADDRESS( MATCH(LOOKUP(ROW($A8),ROW($A$1:$A8)/($A$1:$A8<>""),$A$1:$A8), {"Monday","Tuesday","Wednesday","Thursday","Friday","Saturday"},0)+9, COLUMN()-1 ) ) & ")" )} -> Hindi_Lit (MB) | I8: {=IF( INDIRECT("TT_"&$B8&"!"& ADDRESS( MATCH(LOOKUP(ROW($A8),ROW($A$1:$A8)/($A$1:$A8<>""),$A$1:$A8), {"Monday","Tuesday","Wednesday","Thursday","Friday","Saturday"},0)+1, COLUMN()-1 ) )="","", INDIRECT("TT_"&$B8&"!"& ADDRESS( MATCH(LOOKUP(ROW($A8),ROW($A$1:$A8)/($A$1:$A8<>""),$A$1:$A8), {"Monday","Tuesday","Wednesday","Thursday","Friday","Saturday"},0)+1, COLUMN()-1 ) ) & " (" & INDIRECT("TT_"&$B8&"!"& ADDRESS( MATCH(LOOKUP(ROW($A8),ROW($A$1:$A8)/($A$1:$A8<>""),$A$1:$A8), {"Monday","Tuesday","Wednesday","Thursday","Friday","Saturday"},0)+9, COLUMN()-1 ) ) & ")" )} -> Games (SZ) | J8: {=IF( INDIRECT("TT_"&$B8&"!"& ADDRESS( MATCH(LOOKUP(ROW($A8),ROW($A$1:$A8)/($A$1:$A8<>""),$A$1:$A8), {"Monday","Tuesday","Wednesday","Thursday","Friday","Saturday"},0)+1, COLUMN()-1 ) )="","", INDIRECT("TT_"&$B8&"!"& ADDRESS( MATCH(LOOKUP(ROW($A8),ROW($A$1:$A8)/($A$1:$A8<>""),$A$1:$A8), {"Monday","Tuesday","Wednesday","Thursday","Friday","Saturday"},0)+1, COLUMN()-1 ) ) & " (" & INDIRECT("TT_"&$B8&"!"& ADDRESS( MATCH(LOOKUP(ROW($A8),ROW($A$1:$A8)/($A$1:$A8<>""),$A$1:$A8), {"Monday","Tuesday","Wednesday","Thursday","Friday","Saturday"},0)+9, COLUMN()-1 ) ) & ")" )} -> Maths (SU)
B9: 4a | C9: {=IF( INDIRECT("TT_"&$B9&"!"& ADDRESS( MATCH(LOOKUP(ROW($A9),ROW($A$1:$A9)/($A$1:$A9<>""),$A$1:$A9), {"Monday","Tuesday","Wednesday","Thursday","Friday","Saturday"},0)+1, COLUMN()-1 ) )="","", INDIRECT("TT_"&$B9&"!"& ADDRESS( MATCH(LOOKUP(ROW($A9),ROW($A$1:$A9)/($A$1:$A9<>""),$A$1:$A9), {"Monday","Tuesday","Wednesday","Thursday","Friday","Saturday"},0)+1, COLUMN()-1 ) ) & " (" & INDIRECT("TT_"&$B9&"!"& ADDRESS( MATCH(LOOKUP(ROW($A9),ROW($A$1:$A9)/($A$1:$A9<>""),$A$1:$A9), {"Monday","Tuesday","Wednesday","Thursday","Friday","Saturday"},0)+9, COLUMN()-1 ) ) & ")" )} -> Science (VR) | D9: {=IF( INDIRECT("TT_"&$B9&"!"& ADDRESS( MATCH(LOOKUP(ROW($A9),ROW($A$1:$A9)/($A$1:$A9<>""),$A$1:$A9), {"Monday","Tuesday","Wednesday","Thursday","Friday","Saturday"},0)+1, COLUMN()-1 ) )="","", INDIRECT("TT_"&$B9&"!"& ADDRESS( MATCH(LOOKUP(ROW($A9),ROW($A$1:$A9)/($A$1:$A9<>""),$A$1:$A9), {"Monday","Tuesday","Wednesday","Thursday","Friday","Saturday"},0)+1, COLUMN()-1 ) ) & " (" & INDIRECT("TT_"&$B9&"!"& ADDRESS( MATCH(LOOKUP(ROW($A9),ROW($A$1:$A9)/($A$1:$A9<>""),$A$1:$A9), {"Monday","Tuesday","Wednesday","Thursday","Friday","Saturday"},0)+9, COLUMN()-1 ) ) & ")" )} -> Hindi_Lit (MB) | E9: {=IF( INDIRECT("TT_"&$B9&"!"& ADDRESS( MATCH(LOOKUP(ROW($A9),ROW($A$1:$A9)/($A$1:$A9<>""),$A$1:$A9), {"Monday","Tuesday","Wednesday","Thursday","Friday","Saturday"},0)+1, COLUMN()-1 ) )="","", INDIRECT("TT_"&$B9&"!"& ADDRESS( MATCH(LOOKUP(ROW($A9),ROW($A$1:$A9)/($A$1:$A9<>""),$A$1:$A9), {"Monday","Tuesday","Wednesday","Thursday","Friday","Saturday"},0)+1, COLUMN()-1 ) ) & " (" & INDIRECT("TT_"&$B9&"!"& ADDRESS( MATCH(LOOKUP(ROW($A9),ROW($A$1:$A9)/($A$1:$A9<>""),$A$1:$A9), {"Monday","Tuesday","Wednesday","Thursday","Friday","Saturday"},0)+9, COLUMN()-1 ) ) & ")" )} -> English_Lit (AN) | F9: {=IF( INDIRECT("TT_"&$B9&"!"& ADDRESS( MATCH(LOOKUP(ROW($A9),ROW($A$1:$A9)/($A$1:$A9<>""),$A$1:$A9), {"Monday","Tuesday","Wednesday","Thursday","Friday","Saturday"},0)+1, COLUMN()-1 ) )="","", INDIRECT("TT_"&$B9&"!"& ADDRESS( MATCH(LOOKUP(ROW($A9),ROW($A$1:$A9)/($A$1:$A9<>""),$A$1:$A9), {"Monday","Tuesday","Wednesday","Thursday","Friday","Saturday"},0)+1, COLUMN()-1 ) ) & " (" & INDIRECT("TT_"&$B9&"!"& ADDRESS( MATCH(LOOKUP(ROW($A9),ROW($A$1:$A9)/($A$1:$A9<>""),$A$1:$A9), {"Monday","Tuesday","Wednesday","Thursday","Friday","Saturday"},0)+9, COLUMN()-1 ) ) & ")" )} -> SSt (NT) | G9: {=IF( INDIRECT("TT_"&$B9&"!"& ADDRESS( MATCH(LOOKUP(ROW($A9),ROW($A$1:$A9)/($A$1:$A9<>""),$A$1:$A9), {"Monday","Tuesday","Wednesday","Thursday","Friday","Saturday"},0)+1, COLUMN()-1 ) )="","", INDIRECT("TT_"&$B9&"!"& ADDRESS( MATCH(LOOKUP(ROW($A9),ROW($A$1:$A9)/($A$1:$A9<>""),$A$1:$A9), {"Monday","Tuesday","Wednesday","Thursday","Friday","Saturday"},0)+1, COLUMN()-1 ) ) & " (" & INDIRECT("TT_"&$B9&"!"& ADDRESS( MATCH(LOOKUP(ROW($A9),ROW($A$1:$A9)/($A$1:$A9<>""),$A$1:$A9), {"Monday","Tuesday","Wednesday","Thursday","Friday","Saturday"},0)+9, COLUMN()-1 ) ) & ")" )} -> Games (SZ) | H9: {=IF( INDIRECT("TT_"&$B9&"!"& ADDRESS( MATCH(LOOKUP(ROW($A9),ROW($A$1:$A9)/($A$1:$A9<>""),$A$1:$A9), {"Monday","Tuesday","Wednesday","Thursday","Friday","Saturday"},0)+1, COLUMN()-1 ) )="","", INDIRECT("TT_"&$B9&"!"& ADDRESS( MATCH(LOOKUP(ROW($A9),ROW($A$1:$A9)/($A$1:$A9<>""),$A$1:$A9), {"Monday","Tuesday","Wednesday","Thursday","Friday","Saturday"},0)+1, COLUMN()-1 ) ) & " (" & INDIRECT("TT_"&$B9&"!"& ADDRESS( MATCH(LOOKUP(ROW($A9),ROW($A$1:$A9)/($A$1:$A9<>""),$A$1:$A9), {"Monday","Tuesday","Wednesday","Thursday","Friday","Saturday"},0)+9, COLUMN()-1 ) ) & ")" )} -> Maths (DK) | I9: {=IF( INDIRECT("TT_"&$B9&"!"& ADDRESS( MATCH(LOOKUP(ROW($A9),ROW($A$1:$A9)/($A$1:$A9<>""),$A$1:$A9), {"Monday","Tuesday","Wednesday","Thursday","Friday","Saturday"},0)+1, COLUMN()-1 ) )="","", INDIRECT("TT_"&$B9&"!"& ADDRESS( MATCH(LOOKUP(ROW($A9),ROW($A$1:$A9)/($A$1:$A9<>""),$A$1:$A9), {"Monday","Tuesday","Wednesday","Thursday","Friday","Saturday"},0)+1, COLUMN()-1 ) ) & " (" & INDIRECT("TT_"&$B9&"!"& ADDRESS( MATCH(LOOKUP(ROW($A9),ROW($A$1:$A9)/($A$1:$A9<>""),$A$1:$A9), {"Monday","Tuesday","Wednesday","Thursday","Friday","Saturday"},0)+9, COLUMN()-1 ) ) & ")" )} -> Computer (NP) | J9: {=IF( INDIRECT("TT_"&$B9&"!"& ADDRESS( MATCH(LOOKUP(ROW($A9),ROW($A$1:$A9)/($A$1:$A9<>""),$A$1:$A9), {"Monday","Tuesday","Wednesday","Thursday","Friday","Saturday"},0)+1, COLUMN()-1 ) )="","", INDIRECT("TT_"&$B9&"!"& ADDRESS( MATCH(LOOKUP(ROW($A9),ROW($A$1:$A9)/($A$1:$A9<>""),$A$1:$A9), {"Monday","Tuesday","Wednesday","Thursday","Friday","Saturday"},0)+1, COLUMN()-1 ) ) & " (" & INDIRECT("TT_"&$B9&"!"& ADDRESS( MATCH(LOOKUP(ROW($A9),ROW($A$1:$A9)/($A$1:$A9<>""),$A$1:$A9), {"Monday","Tuesday","Wednesday","Thursday","Friday","Saturday"},0)+9, COLUMN()-1 ) ) & ")" )} -> GK (MP)
B10: 4b | C10: {=IF( INDIRECT("TT_"&$B10&"!"& ADDRESS( MATCH(LOOKUP(ROW($A10),ROW($A$1:$A10)/($A$1:$A10<>""),$A$1:$A10), {"Monday","Tuesday","Wednesday","Thursday","Friday","Saturday"},0)+1, COLUMN()-1 ) )="","", INDIRECT("TT_"&$B10&"!"& ADDRESS( MATCH(LOOKUP(ROW($A10),ROW($A$1:$A10)/($A$1:$A10<>""),$A$1:$A10), {"Monday","Tuesday","Wednesday","Thursday","Friday","Saturday"},0)+1, COLUMN()-1 ) ) & " (" & INDIRECT("TT_"&$B10&"!"& ADDRESS( MATCH(LOOKUP(ROW($A10),ROW($A$1:$A10)/($A$1:$A10<>""),$A$1:$A10), {"Monday","Tuesday","Wednesday","Thursday","Friday","Saturday"},0)+9, COLUMN()-1 ) ) & ")" )} -> Hindi_Lit (MB) | D10: {=IF( INDIRECT("TT_"&$B10&"!"& ADDRESS( MATCH(LOOKUP(ROW($A10),ROW($A$1:$A10)/($A$1:$A10<>""),$A$1:$A10), {"Monday","Tuesday","Wednesday","Thursday","Friday","Saturday"},0)+1, COLUMN()-1 ) )="","", INDIRECT("TT_"&$B10&"!"& ADDRESS( MATCH(LOOKUP(ROW($A10),ROW($A$1:$A10)/($A$1:$A10<>""),$A$1:$A10), {"Monday","Tuesday","Wednesday","Thursday","Friday","Saturday"},0)+1, COLUMN()-1 ) ) & " (" & INDIRECT("TT_"&$B10&"!"& ADDRESS( MATCH(LOOKUP(ROW($A10),ROW($A$1:$A10)/($A$1:$A10<>""),$A$1:$A10), {"Monday","Tuesday","Wednesday","Thursday","Friday","Saturday"},0)+9, COLUMN()-1 ) ) & ")" )} -> Maths (DK) | E10: {=IF( INDIRECT("TT_"&$B10&"!"& ADDRESS( MATCH(LOOKUP(ROW($A10),ROW($A$1:$A10)/($A$1:$A10<>""),$A$1:$A10), {"Monday","Tuesday","Wednesday","Thursday","Friday","Saturday"},0)+1, COLUMN()-1 ) )="","", INDIRECT("TT_"&$B10&"!"& ADDRESS( MATCH(LOOKUP(ROW($A10),ROW($A$1:$A10)/($A$1:$A10<>""),$A$1:$A10), {"Monday","Tuesday","Wednesday","Thursday","Friday","Saturday"},0)+1, COLUMN()-1 ) ) & " (" & INDIRECT("TT_"&$B10&"!"& ADDRESS( MATCH(LOOKUP(ROW($A10),ROW($A$1:$A10)/($A$1:$A10<>""),$A$1:$A10), {"Monday","Tuesday","Wednesday","Thursday","Friday","Saturday"},0)+9, COLUMN()-1 ) ) & ")" )} -> Skating (SZ) | F10: {=IF( INDIRECT("TT_"&$B10&"!"& ADDRESS( MATCH(LOOKUP(ROW($A10),ROW($A$1:$A10)/($A$1:$A10<>""),$A$1:$A10), {"Monday","Tuesday","Wednesday","Thursday","Friday","Saturday"},0)+1, COLUMN()-1 ) )="","", INDIRECT("TT_"&$B10&"!"& ADDRESS( MATCH(LOOKUP(ROW($A10),ROW($A$1:$A10)/($A$1:$A10<>""),$A$1:$A10), {"Monday","Tuesday","Wednesday","Thursday","Friday","Saturday"},0)+1, COLUMN()-1 ) ) & " (" & INDIRECT("TT_"&$B10&"!"& ADDRESS( MATCH(LOOKUP(ROW($A10),ROW($A$1:$A10)/($A$1:$A10<>""),$A$1:$A10), {"Monday","Tuesday","Wednesday","Thursday","Friday","Saturday"},0)+9, COLUMN()-1 ) ) & ")" )} -> English_Lit (KB) | G10: {=IF( INDIRECT("TT_"&$B10&"!"& ADDRESS( MATCH(LOOKUP(ROW($A10),ROW($A$1:$A10)/($A$1:$A10<>""),$A$1:$A10), {"Monday","Tuesday","Wednesday","Thursday","Friday","Saturday"},0)+1, COLUMN()-1 ) )="","", INDIRECT("TT_"&$B10&"!"& ADDRESS( MATCH(LOOKUP(ROW($A10),ROW($A$1:$A10)/($A$1:$A10<>""),$A$1:$A10), {"Monday","Tuesday","Wednesday","Thursday","Friday","Saturday"},0)+1, COLUMN()-1 ) ) & " (" & INDIRECT("TT_"&$B10&"!"& ADDRESS( MATCH(LOOKUP(ROW($A10),ROW($A$1:$A10)/($A$1:$A10<>""),$A$1:$A10), {"Monday","Tuesday","Wednesday","Thursday","Friday","Saturday"},0)+9, COLUMN()-1 ) ) & ")" )} -> Science (VR) | H10: {=IF( INDIRECT("TT_"&$B10&"!"& ADDRESS( MATCH(LOOKUP(ROW($A10),ROW($A$1:$A10)/($A$1:$A10<>""),$A$1:$A10), {"Monday","Tuesday","Wednesday","Thursday","Friday","Saturday"},0)+1, COLUMN()-1 ) )="","", INDIRECT("TT_"&$B10&"!"& ADDRESS( MATCH(LOOKUP(ROW($A10),ROW($A$1:$A10)/($A$1:$A10<>""),$A$1:$A10), {"Monday","Tuesday","Wednesday","Thursday","Friday","Saturday"},0)+1, COLUMN()-1 ) ) & " (" & INDIRECT("TT_"&$B10&"!"& ADDRESS( MATCH(LOOKUP(ROW($A10),ROW($A$1:$A10)/($A$1:$A10<>""),$A$1:$A10), {"Monday","Tuesday","Wednesday","Thursday","Friday","Saturday"},0)+9, COLUMN()-1 ) ) & ")" )} -> Music (MG) | I10: {=IF( INDIRECT("TT_"&$B10&"!"& ADDRESS( MATCH(LOOKUP(ROW($A10),ROW($A$1:$A10)/($A$1:$A10<>""),$A$1:$A10), {"Monday","Tuesday","Wednesday","Thursday","Friday","Saturday"},0)+1, COLUMN()-1 ) )="","", INDIRECT("TT_"&$B10&"!"& ADDRESS( MATCH(LOOKUP(ROW($A10),ROW($A$1:$A10)/($A$1:$A10<>""),$A$1:$A10), {"Monday","Tuesday","Wednesday","Thursday","Friday","Saturday"},0)+1, COLUMN()-1 ) ) & " (" & INDIRECT("TT_"&$B10&"!"& ADDRESS( MATCH(LOOKUP(ROW($A10),ROW($A$1:$A10)/($A$1:$A10<>""),$A$1:$A10), {"Monday","Tuesday","Wednesday","Thursday","Friday","Saturday"},0)+9, COLUMN()-1 ) ) & ")" )} -> SSt (NT) | J10: {=IF( INDIRECT("TT_"&$B10&"!"& ADDRESS( MATCH(LOOKUP(ROW($A10),ROW($A$1:$A10)/($A$1:$A10<>""),$A$1:$A10), {"Monday","Tuesday","Wednesday","Thursday","Friday","Saturday"},0)+1, COLUMN()-1 ) )="","", INDIRECT("TT_"&$B10&"!"& ADDRESS( MATCH(LOOKUP(ROW($A10),ROW($A$1:$A10)/($A$1:$A10<>""),$A$1:$A10), {"Monday","Tuesday","Wednesday","Thursday","Friday","Saturday"},0)+1, COLUMN()-1 ) ) & " (" & INDIRECT("TT_"&$B10&"!"& ADDRESS( MATCH(LOOKUP(ROW($A10),ROW($A$1:$A10)/($A$1:$A10<>""),$A$1:$A10), {"Monday","Tuesday","Wednesday","Thursday","Friday","Saturday"},0)+9, COLUMN()-1 ) ) & ")" )} -> STEM_Junior (NP)
B11: 5a | C11: {=IF( INDIRECT("TT_"&$B11&"!"& ADDRESS( MATCH(LOOKUP(ROW($A11),ROW($A$1:$A11)/($A$1:$A11<>""),$A$1:$A11), {"Monday","Tuesday","Wednesday","Thursday","Friday","Saturday"},0)+1, COLUMN()-1 ) )="","", INDIRECT("TT_"&$B11&"!"& ADDRESS( MATCH(LOOKUP(ROW($A11),ROW($A$1:$A11)/($A$1:$A11<>""),$A$1:$A11), {"Monday","Tuesday","Wednesday","Thursday","Friday","Saturday"},0)+1, COLUMN()-1 ) ) & " (" & INDIRECT("TT_"&$B11&"!"& ADDRESS( MATCH(LOOKUP(ROW($A11),ROW($A$1:$A11)/($A$1:$A11<>""),$A$1:$A11), {"Monday","Tuesday","Wednesday","Thursday","Friday","Saturday"},0)+9, COLUMN()-1 ) ) & ")" )} -> SSt (NT) | D11: {=IF( INDIRECT("TT_"&$B11&"!"& ADDRESS( MATCH(LOOKUP(ROW($A11),ROW($A$1:$A11)/($A$1:$A11<>""),$A$1:$A11), {"Monday","Tuesday","Wednesday","Thursday","Friday","Saturday"},0)+1, COLUMN()-1 ) )="","", INDIRECT("TT_"&$B11&"!"& ADDRESS( MATCH(LOOKUP(ROW($A11),ROW($A$1:$A11)/($A$1:$A11<>""),$A$1:$A11), {"Monday","Tuesday","Wednesday","Thursday","Friday","Saturday"},0)+1, COLUMN()-1 ) ) & " (" & INDIRECT("TT_"&$B11&"!"& ADDRESS( MATCH(LOOKUP(ROW($A11),ROW($A$1:$A11)/($A$1:$A11<>""),$A$1:$A11), {"Monday","Tuesday","Wednesday","Thursday","Friday","Saturday"},0)+9, COLUMN()-1 ) ) & ")" )} -> Computer (NP) | E11: {=IF( INDIRECT("TT_"&$B11&"!"& ADDRESS( MATCH(LOOKUP(ROW($A11),ROW($A$1:$A11)/($A$1:$A11<>""),$A$1:$A11), {"Monday","Tuesday","Wednesday","Thursday","Friday","Saturday"},0)+1, COLUMN()-1 ) )="","", INDIRECT("TT_"&$B11&"!"& ADDRESS( MATCH(LOOKUP(ROW($A11),ROW($A$1:$A11)/($A$1:$A11<>""),$A$1:$A11), {"Monday","Tuesday","Wednesday","Thursday","Friday","Saturday"},0)+1, COLUMN()-1 ) ) & " (" & INDIRECT("TT_"&$B11&"!"& ADDRESS( MATCH(LOOKUP(ROW($A11),ROW($A$1:$A11)/($A$1:$A11<>""),$A$1:$A11), {"Monday","Tuesday","Wednesday","Thursday","Friday","Saturday"},0)+9, COLUMN()-1 ) ) & ")" )} -> Hindi_Lang (MB) | F11: {=IF( INDIRECT("TT_"&$B11&"!"& ADDRESS( MATCH(LOOKUP(ROW($A11),ROW($A$1:$A11)/($A$1:$A11<>""),$A$1:$A11), {"Monday","Tuesday","Wednesday","Thursday","Friday","Saturday"},0)+1, COLUMN()-1 ) )="","", INDIRECT("TT_"&$B11&"!"& ADDRESS( MATCH(LOOKUP(ROW($A11),ROW($A$1:$A11)/($A$1:$A11<>""),$A$1:$A11), {"Monday","Tuesday","Wednesday","Thursday","Friday","Saturday"},0)+1, COLUMN()-1 ) ) & " (" & INDIRECT("TT_"&$B11&"!"& ADDRESS( MATCH(LOOKUP(ROW($A11),ROW($A$1:$A11)/($A$1:$A11<>""),$A$1:$A11), {"Monday","Tuesday","Wednesday","Thursday","Friday","Saturday"},0)+9, COLUMN()-1 ) ) & ")" )} -> Maths (NG) | G11: {=IF( INDIRECT("TT_"&$B11&"!"& ADDRESS( MATCH(LOOKUP(ROW($A11),ROW($A$1:$A11)/($A$1:$A11<>""),$A$1:$A11), {"Monday","Tuesday","Wednesday","Thursday","Friday","Saturday"},0)+1, COLUMN()-1 ) )="","", INDIRECT("TT_"&$B11&"!"& ADDRESS( MATCH(LOOKUP(ROW($A11),ROW($A$1:$A11)/($A$1:$A11<>""),$A$1:$A11), {"Monday","Tuesday","Wednesday","Thursday","Friday","Saturday"},0)+1, COLUMN()-1 ) ) & " (" & INDIRECT("TT_"&$B11&"!"& ADDRESS( MATCH(LOOKUP(ROW($A11),ROW($A$1:$A11)/($A$1:$A11<>""),$A$1:$A11), {"Monday","Tuesday","Wednesday","Thursday","Friday","Saturday"},0)+9, COLUMN()-1 ) ) & ")" )} -> Library (SP) | H11: {=IF( INDIRECT("TT_"&$B11&"!"& ADDRESS( MATCH(LOOKUP(ROW($A11),ROW($A$1:$A11)/($A$1:$A11<>""),$A$1:$A11), {"Monday","Tuesday","Wednesday","Thursday","Friday","Saturday"},0)+1, COLUMN()-1 ) )="","", INDIRECT("TT_"&$B11&"!"& ADDRESS( MATCH(LOOKUP(ROW($A11),ROW($A$1:$A11)/($A$1:$A11<>""),$A$1:$A11), {"Monday","Tuesday","Wednesday","Thursday","Friday","Saturday"},0)+1, COLUMN()-1 ) ) & " (" & INDIRECT("TT_"&$B11&"!"& ADDRESS( MATCH(LOOKUP(ROW($A11),ROW($A$1:$A11)/($A$1:$A11<>""),$A$1:$A11), {"Monday","Tuesday","Wednesday","Thursday","Friday","Saturday"},0)+9, COLUMN()-1 ) ) & ")" )} -> Skating (SZ) | I11: {=IF( INDIRECT("TT_"&$B11&"!"& ADDRESS( MATCH(LOOKUP(ROW($A11),ROW($A$1:$A11)/($A$1:$A11<>""),$A$1:$A11), {"Monday","Tuesday","Wednesday","Thursday","Friday","Saturday"},0)+1, COLUMN()-1 ) )="","", INDIRECT("TT_"&$B11&"!"& ADDRESS( MATCH(LOOKUP(ROW($A11),ROW($A$1:$A11)/($A$1:$A11<>""),$A$1:$A11), {"Monday","Tuesday","Wednesday","Thursday","Friday","Saturday"},0)+1, COLUMN()-1 ) ) & " (" & INDIRECT("TT_"&$B11&"!"& ADDRESS( MATCH(LOOKUP(ROW($A11),ROW($A$1:$A11)/($A$1:$A11<>""),$A$1:$A11), {"Monday","Tuesday","Wednesday","Thursday","Friday","Saturday"},0)+9, COLUMN()-1 ) ) & ")" )} -> Science (VR) | J11: {=IF( INDIRECT("TT_"&$B11&"!"& ADDRESS( MATCH(LOOKUP(ROW($A11),ROW($A$1:$A11)/($A$1:$A11<>""),$A$1:$A11), {"Monday","Tuesday","Wednesday","Thursday","Friday","Saturday"},0)+1, COLUMN()-1 ) )="","", INDIRECT("TT_"&$B11&"!"& ADDRESS( MATCH(LOOKUP(ROW($A11),ROW($A$1:$A11)/($A$1:$A11<>""),$A$1:$A11), {"Monday","Tuesday","Wednesday","Thursday","Friday","Saturday"},0)+1, COLUMN()-1 ) ) & " (" & INDIRECT("TT_"&$B11&"!"& ADDRESS( MATCH(LOOKUP(ROW($A11),ROW($A$1:$A11)/($A$1:$A11<>""),$A$1:$A11), {"Monday","Tuesday","Wednesday","Thursday","Friday","Saturday"},0)+9, COLUMN()-1 ) ) & ")" )} -> English_Lit (KB)
B12: 5b | C12: {=IF( INDIRECT("TT_"&$B12&"!"& ADDRESS( MATCH(LOOKUP(ROW($A12),ROW($A$1:$A12)/($A$1:$A12<>""),$A$1:$A12), {"Monday","Tuesday","Wednesday","Thursday","Friday","Saturday"},0)+1, COLUMN()-1 ) )="","", INDIRECT("TT_"&$B12&"!"& ADDRESS( MATCH(LOOKUP(ROW($A12),ROW($A$1:$A12)/($A$1:$A12<>""),$A$1:$A12), {"Monday","Tuesday","Wednesday","Thursday","Friday","Saturday"},0)+1, COLUMN()-1 ) ) & " (" & INDIRECT("TT_"&$B12&"!"& ADDRESS( MATCH(LOOKUP(ROW($A12),ROW($A$1:$A12)/($A$1:$A12<>""),$A$1:$A12), {"Monday","Tuesday","Wednesday","Thursday","Friday","Saturday"},0)+9, COLUMN()-1 ) ) & ")" )} -> Music (MG) | D12: {=IF( INDIRECT("TT_"&$B12&"!"& ADDRESS( MATCH(LOOKUP(ROW($A12),ROW($A$1:$A12)/($A$1:$A12<>""),$A$1:$A12), {"Monday","Tuesday","Wednesday","Thursday","Friday","Saturday"},0)+1, COLUMN()-1 ) )="","", INDIRECT("TT_"&$B12&"!"& ADDRESS( MATCH(LOOKUP(ROW($A12),ROW($A$1:$A12)/($A$1:$A12<>""),$A$1:$A12), {"Monday","Tuesday","Wednesday","Thursday","Friday","Saturday"},0)+1, COLUMN()-1 ) ) & " (" & INDIRECT("TT_"&$B12&"!"& ADDRESS( MATCH(LOOKUP(ROW($A12),ROW($A$1:$A12)/($A$1:$A12<>""),$A$1:$A12), {"Monday","Tuesday","Wednesday","Thursday","Friday","Saturday"},0)+9, COLUMN()-1 ) ) & ")" )} -> Maths (NG) | E12: {=IF( INDIRECT("TT_"&$B12&"!"& ADDRESS( MATCH(LOOKUP(ROW($A12),ROW($A$1:$A12)/($A$1:$A12<>""),$A$1:$A12), {"Monday","Tuesday","Wednesday","Thursday","Friday","Saturday"},0)+1, COLUMN()-1 ) )="","", INDIRECT("TT_"&$B12&"!"& ADDRESS( MATCH(LOOKUP(ROW($A12),ROW($A$1:$A12)/($A$1:$A12<>""),$A$1:$A12), {"Monday","Tuesday","Wednesday","Thursday","Friday","Saturday"},0)+1, COLUMN()-1 ) ) & " (" & INDIRECT("TT_"&$B12&"!"& ADDRESS( MATCH(LOOKUP(ROW($A12),ROW($A$1:$A12)/($A$1:$A12<>""),$A$1:$A12), {"Monday","Tuesday","Wednesday","Thursday","Friday","Saturday"},0)+9, COLUMN()-1 ) ) & ")" )} -> SSt (PR) | F12: {=IF( INDIRECT("TT_"&$B12&"!"& ADDRESS( MATCH(LOOKUP(ROW($A12),ROW($A$1:$A12)/($A$1:$A12<>""),$A$1:$A12), {"Monday","Tuesday","Wednesday","Thursday","Friday","Saturday"},0)+1, COLUMN()-1 ) )="","", INDIRECT("TT_"&$B12&"!"& ADDRESS( MATCH(LOOKUP(ROW($A12),ROW($A$1:$A12)/($A$1:$A12<>""),$A$1:$A12), {"Monday","Tuesday","Wednesday","Thursday","Friday","Saturday"},0)+1, COLUMN()-1 ) ) & " (" & INDIRECT("TT_"&$B12&"!"& ADDRESS( MATCH(LOOKUP(ROW($A12),ROW($A$1:$A12)/($A$1:$A12<>""),$A$1:$A12), {"Monday","Tuesday","Wednesday","Thursday","Friday","Saturday"},0)+9, COLUMN()-1 ) ) & ")" )} -> GK (MP) | G12: {=IF( INDIRECT("TT_"&$B12&"!"& ADDRESS( MATCH(LOOKUP(ROW($A12),ROW($A$1:$A12)/($A$1:$A12<>""),$A$1:$A12), {"Monday","Tuesday","Wednesday","Thursday","Friday","Saturday"},0)+1, COLUMN()-1 ) )="","", INDIRECT("TT_"&$B12&"!"& ADDRESS( MATCH(LOOKUP(ROW($A12),ROW($A$1:$A12)/($A$1:$A12<>""),$A$1:$A12), {"Monday","Tuesday","Wednesday","Thursday","Friday","Saturday"},0)+1, COLUMN()-1 ) ) & " (" & INDIRECT("TT_"&$B12&"!"& ADDRESS( MATCH(LOOKUP(ROW($A12),ROW($A$1:$A12)/($A$1:$A12<>""),$A$1:$A12), {"Monday","Tuesday","Wednesday","Thursday","Friday","Saturday"},0)+9, COLUMN()-1 ) ) & ")" )} -> English_Lit (KB) | H12: {=IF( INDIRECT("TT_"&$B12&"!"& ADDRESS( MATCH(LOOKUP(ROW($A12),ROW($A$1:$A12)/($A$1:$A12<>""),$A$1:$A12), {"Monday","Tuesday","Wednesday","Thursday","Friday","Saturday"},0)+1, COLUMN()-1 ) )="","", INDIRECT("TT_"&$B12&"!"& ADDRESS( MATCH(LOOKUP(ROW($A12),ROW($A$1:$A12)/($A$1:$A12<>""),$A$1:$A12), {"Monday","Tuesday","Wednesday","Thursday","Friday","Saturday"},0)+1, COLUMN()-1 ) ) & " (" & INDIRECT("TT_"&$B12&"!"& ADDRESS( MATCH(LOOKUP(ROW($A12),ROW($A$1:$A12)/($A$1:$A12<>""),$A$1:$A12), {"Monday","Tuesday","Wednesday","Thursday","Friday","Saturday"},0)+9, COLUMN()-1 ) ) & ")" )} -> Maths (NG) | I12: {=IF( INDIRECT("TT_"&$B12&"!"& ADDRESS( MATCH(LOOKUP(ROW($A12),ROW($A$1:$A12)/($A$1:$A12<>""),$A$1:$A12), {"Monday","Tuesday","Wednesday","Thursday","Friday","Saturday"},0)+1, COLUMN()-1 ) )="","", INDIRECT("TT_"&$B12&"!"& ADDRESS( MATCH(LOOKUP(ROW($A12),ROW($A$1:$A12)/($A$1:$A12<>""),$A$1:$A12), {"Monday","Tuesday","Wednesday","Thursday","Friday","Saturday"},0)+1, COLUMN()-1 ) ) & " (" & INDIRECT("TT_"&$B12&"!"& ADDRESS( MATCH(LOOKUP(ROW($A12),ROW($A$1:$A12)/($A$1:$A12<>""),$A$1:$A12), {"Monday","Tuesday","Wednesday","Thursday","Friday","Saturday"},0)+9, COLUMN()-1 ) ) & ")" )} -> Hindi_Lit (MB) | J12: {=IF( INDIRECT("TT_"&$B12&"!"& ADDRESS( MATCH(LOOKUP(ROW($A12),ROW($A$1:$A12)/($A$1:$A12<>""),$A$1:$A12), {"Monday","Tuesday","Wednesday","Thursday","Friday","Saturday"},0)+1, COLUMN()-1 ) )="","", INDIRECT("TT_"&$B12&"!"& ADDRESS( MATCH(LOOKUP(ROW($A12),ROW($A$1:$A12)/($A$1:$A12<>""),$A$1:$A12), {"Monday","Tuesday","Wednesday","Thursday","Friday","Saturday"},0)+1, COLUMN()-1 ) ) & " (" & INDIRECT("TT_"&$B12&"!"& ADDRESS( MATCH(LOOKUP(ROW($A12),ROW($A$1:$A12)/($A$1:$A12<>""),$A$1:$A12), {"Monday","Tuesday","Wednesday","Thursday","Friday","Saturday"},0)+9, COLUMN()-1 ) ) & ")" )} -> Skating (SZ)
B13: 6a | C13: {=IF( INDIRECT("TT_"&$B13&"!"& ADDRESS( MATCH(LOOKUP(ROW($A13),ROW($A$1:$A13)/($A$1:$A13<>""),$A$1:$A13), {"Monday","Tuesday","Wednesday","Thursday","Friday","Saturday"},0)+1, COLUMN()-1 ) )="","", INDIRECT("TT_"&$B13&"!"& ADDRESS( MATCH(LOOKUP(ROW($A13),ROW($A$1:$A13)/($A$1:$A13<>""),$A$1:$A13), {"Monday","Tuesday","Wednesday","Thursday","Friday","Saturday"},0)+1, COLUMN()-1 ) ) & " (" & INDIRECT("TT_"&$B13&"!"& ADDRESS( MATCH(LOOKUP(ROW($A13),ROW($A$1:$A13)/($A$1:$A13<>""),$A$1:$A13), {"Monday","Tuesday","Wednesday","Thursday","Friday","Saturday"},0)+9, COLUMN()-1 ) ) & ")" )} -> A/C (MP) | D13: {=IF( INDIRECT("TT_"&$B13&"!"& ADDRESS( MATCH(LOOKUP(ROW($A13),ROW($A$1:$A13)/($A$1:$A13<>""),$A$1:$A13), {"Monday","Tuesday","Wednesday","Thursday","Friday","Saturday"},0)+1, COLUMN()-1 ) )="","", INDIRECT("TT_"&$B13&"!"& ADDRESS( MATCH(LOOKUP(ROW($A13),ROW($A$1:$A13)/($A$1:$A13<>""),$A$1:$A13), {"Monday","Tuesday","Wednesday","Thursday","Friday","Saturday"},0)+1, COLUMN()-1 ) ) & " (" & INDIRECT("TT_"&$B13&"!"& ADDRESS( MATCH(LOOKUP(ROW($A13),ROW($A$1:$A13)/($A$1:$A13<>""),$A$1:$A13), {"Monday","Tuesday","Wednesday","Thursday","Friday","Saturday"},0)+9, COLUMN()-1 ) ) & ")" )} -> SST (PR) | E13: {=IF( INDIRECT("TT_"&$B13&"!"& ADDRESS( MATCH(LOOKUP(ROW($A13),ROW($A$1:$A13)/($A$1:$A13<>""),$A$1:$A13), {"Monday","Tuesday","Wednesday","Thursday","Friday","Saturday"},0)+1, COLUMN()-1 ) )="","", INDIRECT("TT_"&$B13&"!"& ADDRESS( MATCH(LOOKUP(ROW($A13),ROW($A$1:$A13)/($A$1:$A13<>""),$A$1:$A13), {"Monday","Tuesday","Wednesday","Thursday","Friday","Saturday"},0)+1, COLUMN()-1 ) ) & " (" & INDIRECT("TT_"&$B13&"!"& ADDRESS( MATCH(LOOKUP(ROW($A13),ROW($A$1:$A13)/($A$1:$A13<>""),$A$1:$A13), {"Monday","Tuesday","Wednesday","Thursday","Friday","Saturday"},0)+9, COLUMN()-1 ) ) & ")" )} -> English_Lit (RD) | F13: {=IF( INDIRECT("TT_"&$B13&"!"& ADDRESS( MATCH(LOOKUP(ROW($A13),ROW($A$1:$A13)/($A$1:$A13<>""),$A$1:$A13), {"Monday","Tuesday","Wednesday","Thursday","Friday","Saturday"},0)+1, COLUMN()-1 ) )="","", INDIRECT("TT_"&$B13&"!"& ADDRESS( MATCH(LOOKUP(ROW($A13),ROW($A$1:$A13)/($A$1:$A13<>""),$A$1:$A13), {"Monday","Tuesday","Wednesday","Thursday","Friday","Saturday"},0)+1, COLUMN()-1 ) ) & " (" & INDIRECT("TT_"&$B13&"!"& ADDRESS( MATCH(LOOKUP(ROW($A13),ROW($A$1:$A13)/($A$1:$A13<>""),$A$1:$A13), {"Monday","Tuesday","Wednesday","Thursday","Friday","Saturday"},0)+9, COLUMN()-1 ) ) & ")" )} -> Dance (SL) | G13: {=IF( INDIRECT("TT_"&$B13&"!"& ADDRESS( MATCH(LOOKUP(ROW($A13),ROW($A$1:$A13)/($A$1:$A13<>""),$A$1:$A13), {"Monday","Tuesday","Wednesday","Thursday","Friday","Saturday"},0)+1, COLUMN()-1 ) )="","", INDIRECT("TT_"&$B13&"!"& ADDRESS( MATCH(LOOKUP(ROW($A13),ROW($A$1:$A13)/($A$1:$A13<>""),$A$1:$A13), {"Monday","Tuesday","Wednesday","Thursday","Friday","Saturday"},0)+1, COLUMN()-1 ) ) & " (" & INDIRECT("TT_"&$B13&"!"& ADDRESS( MATCH(LOOKUP(ROW($A13),ROW($A$1:$A13)/($A$1:$A13<>""),$A$1:$A13), {"Monday","Tuesday","Wednesday","Thursday","Friday","Saturday"},0)+9, COLUMN()-1 ) ) & ")" )} -> Maths (NG) | H13: {=IF( INDIRECT("TT_"&$B13&"!"& ADDRESS( MATCH(LOOKUP(ROW($A13),ROW($A$1:$A13)/($A$1:$A13<>""),$A$1:$A13), {"Monday","Tuesday","Wednesday","Thursday","Friday","Saturday"},0)+1, COLUMN()-1 ) )="","", INDIRECT("TT_"&$B13&"!"& ADDRESS( MATCH(LOOKUP(ROW($A13),ROW($A$1:$A13)/($A$1:$A13<>""),$A$1:$A13), {"Monday","Tuesday","Wednesday","Thursday","Friday","Saturday"},0)+1, COLUMN()-1 ) ) & " (" & INDIRECT("TT_"&$B13&"!"& ADDRESS( MATCH(LOOKUP(ROW($A13),ROW($A$1:$A13)/($A$1:$A13<>""),$A$1:$A13), {"Monday","Tuesday","Wednesday","Thursday","Friday","Saturday"},0)+9, COLUMN()-1 ) ) & ")" )} -> F/S (SW,MS) | I13: {=IF( INDIRECT("TT_"&$B13&"!"& ADDRESS( MATCH(LOOKUP(ROW($A13),ROW($A$1:$A13)/($A$1:$A13<>""),$A$1:$A13), {"Monday","Tuesday","Wednesday","Thursday","Friday","Saturday"},0)+1, COLUMN()-1 ) )="","", INDIRECT("TT_"&$B13&"!"& ADDRESS( MATCH(LOOKUP(ROW($A13),ROW($A$1:$A13)/($A$1:$A13<>""),$A$1:$A13), {"Monday","Tuesday","Wednesday","Thursday","Friday","Saturday"},0)+1, COLUMN()-1 ) ) & " (" & INDIRECT("TT_"&$B13&"!"& ADDRESS( MATCH(LOOKUP(ROW($A13),ROW($A$1:$A13)/($A$1:$A13<>""),$A$1:$A13), {"Monday","Tuesday","Wednesday","Thursday","Friday","Saturday"},0)+9, COLUMN()-1 ) ) & ")" )} -> Skill (GA,SA,HSC) | J13: {=IF( INDIRECT("TT_"&$B13&"!"& ADDRESS( MATCH(LOOKUP(ROW($A13),ROW($A$1:$A13)/($A$1:$A13<>""),$A$1:$A13), {"Monday","Tuesday","Wednesday","Thursday","Friday","Saturday"},0)+1, COLUMN()-1 ) )="","", INDIRECT("TT_"&$B13&"!"& ADDRESS( MATCH(LOOKUP(ROW($A13),ROW($A$1:$A13)/($A$1:$A13<>""),$A$1:$A13), {"Monday","Tuesday","Wednesday","Thursday","Friday","Saturday"},0)+1, COLUMN()-1 ) ) & " (" & INDIRECT("TT_"&$B13&"!"& ADDRESS( MATCH(LOOKUP(ROW($A13),ROW($A$1:$A13)/($A$1:$A13<>""),$A$1:$A13), {"Monday","Tuesday","Wednesday","Thursday","Friday","Saturday"},0)+9, COLUMN()-1 ) ) & ")" )} -> Science (SB)
B14: 6b | C14: {=IF( INDIRECT("TT_"&$B14&"!"& ADDRESS( MATCH(LOOKUP(ROW($A14),ROW($A$1:$A14)/($A$1:$A14<>""),$A$1:$A14), {"Monday","Tuesday","Wednesday","Thursday","Friday","Saturday"},0)+1, COLUMN()-1 ) )="","", INDIRECT("TT_"&$B14&"!"& ADDRESS( MATCH(LOOKUP(ROW($A14),ROW($A$1:$A14)/($A$1:$A14<>""),$A$1:$A14), {"Monday","Tuesday","Wednesday","Thursday","Friday","Saturday"},0)+1, COLUMN()-1 ) ) & " (" & INDIRECT("TT_"&$B14&"!"& ADDRESS( MATCH(LOOKUP(ROW($A14),ROW($A$1:$A14)/($A$1:$A14<>""),$A$1:$A14), {"Monday","Tuesday","Wednesday","Thursday","Friday","Saturday"},0)+9, COLUMN()-1 ) ) & ")" )} -> Hindi_Lit (MS) | D14: {=IF( INDIRECT("TT_"&$B14&"!"& ADDRESS( MATCH(LOOKUP(ROW($A14),ROW($A$1:$A14)/($A$1:$A14<>""),$A$1:$A14), {"Monday","Tuesday","Wednesday","Thursday","Friday","Saturday"},0)+1, COLUMN()-1 ) )="","", INDIRECT("TT_"&$B14&"!"& ADDRESS( MATCH(LOOKUP(ROW($A14),ROW($A$1:$A14)/($A$1:$A14<>""),$A$1:$A14), {"Monday","Tuesday","Wednesday","Thursday","Friday","Saturday"},0)+1, COLUMN()-1 ) ) & " (" & INDIRECT("TT_"&$B14&"!"& ADDRESS( MATCH(LOOKUP(ROW($A14),ROW($A$1:$A14)/($A$1:$A14<>""),$A$1:$A14), {"Monday","Tuesday","Wednesday","Thursday","Friday","Saturday"},0)+9, COLUMN()-1 ) ) & ")" )} -> English_Lit (RD) | E14: {=IF( INDIRECT("TT_"&$B14&"!"& ADDRESS( MATCH(LOOKUP(ROW($A14),ROW($A$1:$A14)/($A$1:$A14<>""),$A$1:$A14), {"Monday","Tuesday","Wednesday","Thursday","Friday","Saturday"},0)+1, COLUMN()-1 ) )="","", INDIRECT("TT_"&$B14&"!"& ADDRESS( MATCH(LOOKUP(ROW($A14),ROW($A$1:$A14)/($A$1:$A14<>""),$A$1:$A14), {"Monday","Tuesday","Wednesday","Thursday","Friday","Saturday"},0)+1, COLUMN()-1 ) ) & " (" & INDIRECT("TT_"&$B14&"!"& ADDRESS( MATCH(LOOKUP(ROW($A14),ROW($A$1:$A14)/($A$1:$A14<>""),$A$1:$A14), {"Monday","Tuesday","Wednesday","Thursday","Friday","Saturday"},0)+9, COLUMN()-1 ) ) & ")" )} -> Science (AB) | F14: {=IF( INDIRECT("TT_"&$B14&"!"& ADDRESS( MATCH(LOOKUP(ROW($A14),ROW($A$1:$A14)/($A$1:$A14<>""),$A$1:$A14), {"Monday","Tuesday","Wednesday","Thursday","Friday","Saturday"},0)+1, COLUMN()-1 ) )="","", INDIRECT("TT_"&$B14&"!"& ADDRESS( MATCH(LOOKUP(ROW($A14),ROW($A$1:$A14)/($A$1:$A14<>""),$A$1:$A14), {"Monday","Tuesday","Wednesday","Thursday","Friday","Saturday"},0)+1, COLUMN()-1 ) ) & " (" & INDIRECT("TT_"&$B14&"!"& ADDRESS( MATCH(LOOKUP(ROW($A14),ROW($A$1:$A14)/($A$1:$A14<>""),$A$1:$A14), {"Monday","Tuesday","Wednesday","Thursday","Friday","Saturday"},0)+9, COLUMN()-1 ) ) & ")" )} -> Computer (NP) | G14: {=IF( INDIRECT("TT_"&$B14&"!"& ADDRESS( MATCH(LOOKUP(ROW($A14),ROW($A$1:$A14)/($A$1:$A14<>""),$A$1:$A14), {"Monday","Tuesday","Wednesday","Thursday","Friday","Saturday"},0)+1, COLUMN()-1 ) )="","", INDIRECT("TT_"&$B14&"!"& ADDRESS( MATCH(LOOKUP(ROW($A14),ROW($A$1:$A14)/($A$1:$A14<>""),$A$1:$A14), {"Monday","Tuesday","Wednesday","Thursday","Friday","Saturday"},0)+1, COLUMN()-1 ) ) & " (" & INDIRECT("TT_"&$B14&"!"& ADDRESS( MATCH(LOOKUP(ROW($A14),ROW($A$1:$A14)/($A$1:$A14<>""),$A$1:$A14), {"Monday","Tuesday","Wednesday","Thursday","Friday","Saturday"},0)+9, COLUMN()-1 ) ) & ")" )} -> Computer (NP) | H14: {=IF( INDIRECT("TT_"&$B14&"!"& ADDRESS( MATCH(LOOKUP(ROW($A14),ROW($A$1:$A14)/($A$1:$A14<>""),$A$1:$A14), {"Monday","Tuesday","Wednesday","Thursday","Friday","Saturday"},0)+1, COLUMN()-1 ) )="","", INDIRECT("TT_"&$B14&"!"& ADDRESS( MATCH(LOOKUP(ROW($A14),ROW($A$1:$A14)/($A$1:$A14<>""),$A$1:$A14), {"Monday","Tuesday","Wednesday","Thursday","Friday","Saturday"},0)+1, COLUMN()-1 ) ) & " (" & INDIRECT("TT_"&$B14&"!"& ADDRESS( MATCH(LOOKUP(ROW($A14),ROW($A$1:$A14)/($A$1:$A14<>""),$A$1:$A14), {"Monday","Tuesday","Wednesday","Thursday","Friday","Saturday"},0)+9, COLUMN()-1 ) ) & ")" )} -> F/S (SW,MS) | I14: {=IF( INDIRECT("TT_"&$B14&"!"& ADDRESS( MATCH(LOOKUP(ROW($A14),ROW($A$1:$A14)/($A$1:$A14<>""),$A$1:$A14), {"Monday","Tuesday","Wednesday","Thursday","Friday","Saturday"},0)+1, COLUMN()-1 ) )="","", INDIRECT("TT_"&$B14&"!"& ADDRESS( MATCH(LOOKUP(ROW($A14),ROW($A$1:$A14)/($A$1:$A14<>""),$A$1:$A14), {"Monday","Tuesday","Wednesday","Thursday","Friday","Saturday"},0)+1, COLUMN()-1 ) ) & " (" & INDIRECT("TT_"&$B14&"!"& ADDRESS( MATCH(LOOKUP(ROW($A14),ROW($A$1:$A14)/($A$1:$A14<>""),$A$1:$A14), {"Monday","Tuesday","Wednesday","Thursday","Friday","Saturday"},0)+9, COLUMN()-1 ) ) & ")" )} -> Maths (NG) | J14: {=IF( INDIRECT("TT_"&$B14&"!"& ADDRESS( MATCH(LOOKUP(ROW($A14),ROW($A$1:$A14)/($A$1:$A14<>""),$A$1:$A14), {"Monday","Tuesday","Wednesday","Thursday","Friday","Saturday"},0)+1, COLUMN()-1 ) )="","", INDIRECT("TT_"&$B14&"!"& ADDRESS( MATCH(LOOKUP(ROW($A14),ROW($A$1:$A14)/($A$1:$A14<>""),$A$1:$A14), {"Monday","Tuesday","Wednesday","Thursday","Friday","Saturday"},0)+1, COLUMN()-1 ) ) & " (" & INDIRECT("TT_"&$B14&"!"& ADDRESS( MATCH(LOOKUP(ROW($A14),ROW($A$1:$A14)/($A$1:$A14<>""),$A$1:$A14), {"Monday","Tuesday","Wednesday","Thursday","Friday","Saturday"},0)+9, COLUMN()-1 ) ) & ")" )} -> SST (PR)
